Workbook
Name fTeam: Dashboard!$H$25
Name Slicer_City2: #N/A
Name Slicer_Stadium2: #N/A
Name Slicer_Team: #N/A
Name Slicer_Toss_Decision2: #N/A
Name Slicer_Winning_Team2: #N/A

Sheet CWC2023
A1: Match ID | B1: Match Date | C1: Match Time | D1: City | E1: Stadium | F1: Team A | G1: Team B | H1: Toss Winner | I1: Toss Decision | J1: Score A | K1: Wickets A | L1: Overs Played A | M1: Maiden Overs A | N1: 4s A | O1: 6s A | P1: Boundaries A | Q1: Runrate A | R1: Leg Byes A | S1: Byes A | T1: Wides A | U1: No Balls A | V1: Penalty A | W1: Extras A | X1: Score B | Y1: Wickets B | Z1: Overs Played B | AA1: Maiden Overs B | AB1: 4s B | AC1: 6s B | AD1: Boundaries B | AE1: Runrate B | AF1: Leg Byes B | AG1: Byes B | AH1: Wides B | AI1: No Balls B | AJ1: Penalty B | AK1: Extras B | AL1: Wining Team | AM1: Margin | AN1: Man of the Match | AO1: Umpire 1 | AP1: Umpire 2 | AQ1: TV Umpire | AR1: Match Refree
A2: 1 | B2: 45056 | C2: 0.58333333 | D2: Ahmedabad | E2: Narendra Modi Stadium | F2: England | G2: NewZealand | H2: NewZealand | I2: Field | J2: 282 | K2: 9 | L2: 50 | M2: 2 | N2: 21 | O2: 6 | P2: 27 | Q2: 5.64 | R2: 1 | S2: 4 | T2: 3 | U2: 0 | V2: 0 | W2: 8 | X2: 283 | Y2: 1 | Z2: 36.2 | AA2: 2 | AB2: 30 | AC2: 8 | AD2: 38 | AE2: 7.78 | AF2: 0 | AG2: 0 | AH2: 6 | AI2: 0 | AJ2: 0 | AK2: 6 | AL2: NewZealand | AM2: 9 Wickets | AN2: Rachin Ravindra | AO2: Kumar Dharmasena | AP2: Nitin Menon | AQ2: Paul Wilson | AR2: Javagal Srinath
A3: 2 | B3: 45087 | C3: 0.58333333 | D3: Hyderabad | E3: Eden Gardens | F3: Pakistan | G3: Netherlands | H3: Netherlands | I3: Field | J3: 286 | K3: 10 | L3: 49 | M3: 1 | N3: 33 | O3: 3 | P3: 36 | Q3: 5.83 | R3: 0 | S3: 0 | T3: 9 | U3: 0 | V3: 0 | W3: 9 | X3: 205 | Y3: 10 | Z3: 41 | AA3: 1 | AB3: 20 | AC3: 4 | AD3: 24 | AE3: 5 | AF3: 0 | AG3: 0 | AH3: 8 | AI3: 1 | AJ3: 0 | AK3: 9 | AL3: Pakistan | AM3: 81 Runs | AN3: Saud Shakeel | AO3: Adrian Holdstock | AP3: Chris Brown | AQ3: Rod Tucker | AR3: Jeff Crowe
A4: 3 | B4: 45117 | C4: 0.58333333 | D4: Dharamshala | E4: HPCA Stadium | F4: Afghanistan | G4: Bangladesh | H4: Bangladesh | I4: Field | J4: 156 | K4: 10 | L4: 37.2 | M4: 1 | N4: 15 | O4: 2 | P4: 17 | Q4: 4.17 | R4: 3 | S4: 0 | T4: 4 | U4: 1 | V4: 0 | W4: 8 | X4: 158 | Y4: 4 | Z4: 34.4 | AA4: 5 | AB4: 13 | AC4: 1 | AD4: 14 | AE4: 4.55 | AF4: 0 | AG4: 0 | AH4: 8 | AI4: 0 | AJ4: 0 | AK4: 8 | AL4: Bangladesh | AM4: 6 Wickets | AN4: Mehidy Hasan Miraz | AO4: Joel Wilson | AP4: Kumar Dharmasena | AQ4: Ahsan Raza | AR4: Andy Pycroft
A5: 4 | B5: 45117 | C5: 0.58333333 | D5: Delhi | E5: Arun Jaitley Stadium | F5: South Africa | G5: Sri Lanka | H5: Sri Lanka | I5: Field | J5: 428 | K5: 5 | L5: 50 | M5: 1 | N5: 45 | O5: 14 | P5: 59 | Q5: 8.56 | R5: 5 | S5: 0 | T5: 14 | U5: 1 | V5: 0 | W5: 20 | X5: 326 | Y5: 10 | Z5: 44.5 | AA5: 1 | AB5: 31 | AC5: 17 | AD5: 48 | AE5: 7.27 | AF5: 1 | AG5: 0 | AH5: 21 | AI5: 1 | AJ5: 0 | AK5: 23 | AL5: South Africa | AM5: 102 Runs | AN5: Aiden Markram | AO5: Richard Illingworth | AP5: Sharfuddoula | AQ5: Michael Gough | AR5: Javagal Srinath
A6: 5 | B6: 45148 | C6: 0.58333333 | D6: Chennai | E6: M. A. Chidambaram Stadium | F6: Australia | G6: India | H6: Australia | I6: Bat | J6: 199 | K6: 10 | L6: 49.3 | M6: 1 | N6: 16 | O6: 2 | P6: 18 | Q6: 4.02 | R6: 1 | S6: 1 | T6: 5 | U6: 1 | V6: 0 | W6: 8 | X6: 201 | Y6: 4 | Z6: 41.2 | AA6: 4 | AB6: 14 | AC6: 3 | AD6: 17 | AE6: 4.86 | AF6: 6 | AG6: 0 | AH6: 6 | AI6: 0 | AJ6: 0 | AK6: 12 | AL6: India | AM6: 6 wickets | AN6: KL Rahul | AO6: Chris Gaffaney | AP6: Richard Kettleborough | AQ6: Chris Brown | AR6: Richie Richardson
A7: 6 | B7: 45179 | C7: 0.58333333 | D7: Hyderabad | E7: Rajiv Gandhi International Stadium | F7: NewZealand | G7: Netherlands | H7: Netherlands | I7: Field | J7: 322 | K7: 7 | L7: 50 | M7: 0 | N7: 30 | O7: 10 | P7: 40 | Q7: 6.44 | R7: 1 | S7: 0 | T7: 2 | U7: 1 | V7: 0 | W7: 4 | X7: 223 | Y7: 10 | Z7: 46.3 | AA7: 3 | AB7: 19 | AC7: 3 | AD7: 22 | AE7: 4.79 | AF7: 3 | AG7: 0 | AH7: 8 | AI7: 2 | AJ7: 0 | AK7: 13 | AL7: NewZealand | AM7: 99 Runs | AN7: Mitchell Santner | AO7: Paul Reiffel | AP7: Rod Tucker | AQ7: Joel Wilson | AR7: Andy Pycroft
A8: 7 | B8: 45209 | C8: 0.4375 | D8: Dharamshala | E8: HPCA Stadium | F8: England | G8: Bangladesh | H8: Bangladesh | I8: Field | J8: 364 | K8: 9 | L8: 50 | M8: 1 | N8: 41 | O8: 7 | P8: 48 | Q8: 7.28 | R8: 4 | S8: 0 | T8: 3 | U8: 0 | V8: 0 | W8: 7 | X8: 227 | Y8: 10 | Z8: 48.2 | AA8: 0 | AB8: 17 | AC8: 3 | AD8: 20 | AE8: 4.69 | AF8: 2 | AG8: 1 | AH8: 4 | AI8: 0 | AJ8: 0 | AK8: 7 | AL8: England | AM8: 137 Runs | AN8: Dawid Malan | AO8: Ahsan Raza | AP8: Paul Wilson | AQ8: Adrian Holdstock | AR8: Javagal Srinath
A9: 8 | B9: 45209 | C9: 0.58333333 | D9: Hyderabad | E9: Rajiv Gandhi International Stadium | F9: Sri Lanka | G9: Pakistan | H9: Sri Lanka | I9: Bat | J9: 344 | K9: 9 | L9: 50 | M9: 0 | N9: 36 | O9: 9 | P9: 45 | Q9: 6.88 | R9: 0 | S9: 0 | T9: 25 | U9: 1 | V9: 0 | W9: 26 | X9: 345 | Y9: 4 | Z9: 48.2 | AA9: 0 | AB9: 26 | AC9: 6 | AD9: 32 | AE9: 7.13 | AF9: 2 | AG9: 2 | AH9: 9 | AI9: 1 | AJ9: 0 | AK9: 14 | AL9: Pakistan | AM9: 6 Wickets | AN9: Mohammad Rizwan | AO9: Chris Gaffaney | AP9: Alex Wharf | AQ9: Nitin Menon | AR9: Andy Pycroft
A10: 9 | B10: 45240 | C10: 0.58333333 | D10: Delhi | E10: Arun Jaitley Stadium | F10: Afghanistan | G10: India | H10: Afghanistan | I10: Bat | J10: 272 | K10: 8 | L10: 50 | M10: 0 | N10: 25 | O10: 7 | P10: 32 | Q10: 5.44 | R10: 4 | S10: 1 | T10: 10 | U10: 0 | V10: 0 | W10: 15 | X10: 273 | Y10: 2 | Z10: 35 | AA10: 0 | AB10: 28 | AC10: 8 | AD10: 36 | AE10: 7.8 | AF10: 3 | AG10: 2 | AH10: 8 | AI10: 2 | AJ10: 0 | AK10: 15 | AL10: India | AM10: 8 Wickets | AN10: Rohit Sharma | AO10: Michael Gough | AP10: Paul Reiffel | AQ10: Marais Erasmus | AR10: Jeff Crowe
A11: 10 | B11: 45270 | C11: 0.58333333 | D11: Lucknow | E11: BRSABV Ekana Cricket Stadium | F11: South Africa | G11: Australia | H11: Australia | I11: Field | J11: 311 | K11: 7 | L11: 50 | M11: 3 | N11: 26 | O11: 8 | P11: 34 | Q11: 6.22 | R11: 4 | S11: 0 | T11: 11 | U11: 2 | V11: 0 | W11: 17 | X11: 177 | Y11: 10 | Z11: 40.5 | AA11: 2 | AB11: 19 | AC11: 0 | AD11: 19 | AE11: 4.33 | AF11: 2 | AG11: 4 | AH11: 7 | AI11: 0 | AJ11: 0 | AK11: 13 | AL11: South Africa | AM11: 134 Runs | AN11: Quinton de Kock | AO11: Joel Wilson | AP11: Richard Illingworth | AQ11: Richard Kettleborough | AR11: Javagal Srinath
A12: 11 | B12: 13/10/2023 | C12: 0.58333333 | D12: Chennai | E12: M. A. Chidambaram Stadium | F12: Bangladesh | G12: NewZealand | H12: NewZealand | I12: Field | J12: 245 | K12: 9 | L12: 50 | M12: 1 | N12: 20 | O12: 8 | P12: 28 | Q12: 4.9 | R12: 1 | S12: 0 | T12: 10 | U12: 0 | V12: 0 | W12: 11 | X12: 248 | Y12: 2 | Z12: 42.5 | AA12: 1 | AB12: 20 | AC12: 6 | AD12: 26 | AE12: 5.78 | AF12: 1 | AG12: 0 | AH12: 4 | AI12: 4 | AJ12: 0 | AK12: 9 | AL12: NewZealand | AM12: 8 Wickets | AN12: Lockie Ferguson | AO12: Kumar Dharmasena | AP12: Nitin Menon | AQ12: Michael Gough | AR12: Richie Richardson
A13: 12 | B13: 14/10/2023 | C13: 0.58333333 | D13: Ahmedabad | E13: Narendra Modi Stadium | F13: Pakistan | G13: India | H13: India | I13: Field | J13: 191 | K13: 10 | L13: 42.5 | M13: 0 | N13: 26 | O13: 0 | P13: 26 | Q13: 4.45 | R13: 5 | S13: 0 | T13: 1 | U13: 0 | V13: 0 | W13: 6 | X13: 192 | Y13: 3 | Z13: 30.3 | AA13: 1 | AB13: 17 | AC13: 8 | AD13: 25 | AE13: 6.29 | AF13: 2 | AG13: 1 | AH13: 1 | AI13: 0 | AJ13: 0 | AK13: 4 | AL13: India | AM13: 7 Wickets | AN13: Jasprit Bumrah | AO13: Richard Illingworth | AP13: Marais Erasmus | AQ13: Richard Kettleborough | AR13: Andy Pycroft
A14: 13 | B14: 15/10/2023 | C14: 0.58333333 | D14: Delhi | E14: Arun Jaitley Stadium | F14: Afghanistan | G14: England | H14: England | I14: Field | J14: 284 | K14: 10 | L14: 49.5 | M14: 3 | N14: 23 | O14: 8 | P14: 31 | Q14: 5.69 | R14: 4 | S14: 0 | T14: 8 | U14: 1 | V14: 0 | W14: 13 | X14: 215 | Y14: 10 | Z14: 40.3 | AA14: 2 | AB14: 24 | AC14: 1 | AD14: 25 | AE14: 5.3 | AF14: 1 | AG14: 0 | AH14: 11 | AI14: 3 | AJ14: 0 | AK14: 15 | AL14: Afghanistan | AM14: 69 Runs | AN14: Mujeeb Ur Rahman | AO14: Sharfuddoula | AP14: Rod Tucker | AQ14: Paul Reiffel | AR14: Jeff Crowe
A15: 14 | B15: 16/10/2023 | C15: 0.58333333 | D15: Lucknow | E15: BRSABV Ekana Cricket Stadium | F15: Sri Lanka | G15: Australia | H15: Sri Lanka | I15: Bat | J15: 209 | K15: 10 | L15: 43.3 | M15: 2 | N15: 23 | O15: 1 | P15: 24 | Q15: 4.8 | R15: 0 | S15: 0 | T15: 3 | U15: 0 | V15: 0 | W15: 3 | X15: 215 | Y15: 5 | Z15: 35.2 | AA15: 2 | AB15: 22 | AC15: 5 | AD15: 27 | AE15: 6.08 | AF15: 2 | AG15: 2 | AH15: 9 | AI15: 0 | AJ15: 0 | AK15: 13 | AL15: Australia | AM15: 5 Wickets | AN15: Adam Zampa | AO15: Alex Wharf | AP15: Chris Gaffaney | AQ15: Chris Brown | AR15: Richie Richardson
A16: 15 | B16: 17/10/2023 | C16: 0.58333333 | D16: Dharamshala | E16: HPCA Stadium | F16: Netherlands | G16: South Africa | H16: South Africa | I16: Field | J16: 245 | K16: 8 | L16: 43 | M16: 1 | N16: 23 | O16: 6 | P16: 29 | Q16: 5.69 | R16: 2 | S16: 0 | T16: 5 | U16: 1 | V16: 0 | W16: 8 | X16: 207 | Y16: 10 | Z16: 42.5 | AA16: 3 | AB16: 19 | AC16: 5 | AD16: 24 | AE16: 4.83 | AF16: 10 | AG16: 0 | AH16: 21 | AI16: 1 | AJ16: 0 | AK16: 32 | AL16: Netherlands | AM16: 38 Runs | AN16: Scott Edwards | AO16: Richard Kettleborough | AP16: Michael Gough | AQ16: Sharfuddoula | AR16: Jeff Crowe
A17: 16 | B17: 18/10/2023 | C17: 0.58333333 | D17: Chennai | E17: M. A. Chidambaram Stadium | F17: NewZealand | G17: Afghanistan | H17: Afghanistan | I17: Field | J17: 288 | K17: 6 | L17: 50 | M17: 4 | N17: 19 | O17: 11 | P17: 30 | Q17: 5.76 | R17: 0 | S17: 0 | T17: 5 | U17: 0 | V17: 0 | W17: 5 | X17: 139 | Y17: 10 | Z17: 34.4 | AA17: 2 | AB17: 11 | AC17: 2 | AD17: 13 | AE17: 4 | AF17: 4 | AG17: 0 | AH17: 5 | AI17: 1 | AJ17: 0 | AK17: 10 | AL17: NewZealand | AM17: 149 Runs | AN17: Glenn Phillips | AO17: Paul Wilson | AP17: Joel Wilson | AQ17: Alex Wharf | AR17: Javagal Srinath
A18: 17 | B18: 19/10/2023 | C18: 0.58333333 | D18: Pune | E18: Maharashtra Cricket Association Stadium | F18: Bangladesh | G18: India | H18: Bangladesh | I18: Bat | J18: 256 | K18: 8 | L18: 50 | M18: 0 | N18: 18 | O18: 8 | P18: 26 | Q18: 5.12 | R18: 0 | S18: 0 | T18: 2 | U18: 2 | V18: 0 | W18: 4 | X18: 261 | Y18: 3 | Z18: 41.3 | AA18: 1 | AB18: 23 | AC18: 9 | AD18: 32 | AE18: 6.28 | AF18: 1 | AG18: 0 | AH18: 5 | AI18: 0 | AJ18: 0 | AK18: 6 | AL18: India | AM18: 7 Wickets | AN18: Virat Kohli | AO18: Adrian Holdstock | AP18: Richard Kettleborough | AQ18: Kumar Dharmasena | AR18: Andy Pycroft
A19: 18 | B19: 20/10/2023 | C19: 0.58333333 | D19: Bangalore | E19: M. Chinnaswamy Stadium | F19: Australia | G19: Pakistan | H19: Pakistan | I19: Field | J19: 367 | K19: 9 | L19: 50 | M19: 1 | N19: 29 | O19: 19 | P19: 48 | Q19: 7.34 | R19: 7 | S19: 1 | T19: 11 | U19: 0 | V19: 0 | W19: 19 | X19: 305 | Y19: 10 | Z19: 45.3 | AA19: 1 | AB19: 34 | AC19: 6 | AD19: 40 | AE19: 6.7 | AF19: 10 | AG19: 1 | AH19: 14 | AI19: 0 | AJ19: 0 | AK19: 25 | AL19: Australia | AM19: 62 Runs | AN19: David Warner | AO19: Richard Illingworth | AP19: Chris Brown | AQ19: Alex Wharf | AR19: Richie Richardson
A20: 19 | B20: 21/10/2023 | C20: 0.4375 | D20: Lucknow | E20: BRSABV Ekana Cricket Stadium | F20: Netherlands | G20: Sri Lanka | H20: Netherlands | I20: Bat | J20: 262 | K20: 10 | L20: 49.4 | M20: 1 | N20: 14 | O20: 3 | P20: 17 | Q20: 5.27 | R20: 0 | S20: 13 | T20: 11 | U20: 0 | V20: 0 | W20: 24 | X20: 263 | Y20: 5 | Z20: 48.2 | AA20: 2 | AB20: 23 | AC20: 3 | AD20: 26 | AE20: 5.44 | AF20: 1 | AG20: 0 | AH20: 26 | AI20: 1 | AJ20: 5 | AK20: 33 | AL20: Sri Lanka | AM20: 5 Wickets | AN20: Sadeera Samarawickrama | AO20: Ahsan Raza | AP20: Marais Erasmus | AQ20: Rod Tucker | AR20: Jeff Crowe
A21: 20 | B21: 21/10/2023 | C21: 0.58333333 | D21: Mumbai | E21: Wankhede Stadium | F21: South Africa | G21: England | H21: England | I21: Field | J21: 399 | K21: 7 | L21: 50 | M21: 2 | N21: 38 | O21: 13 | P21: 51 | Q21: 7.98 | R21: 9 | S21: 0 | T21: 5 | U21: 1 | V21: 0 | W21: 15 | X21: 170 | Y21: 10 | Z21: 22 | AA21: 1 | AB21: 18 | AC21: 9 | AD21: 27 | AE21: 7.72 | AF21: 3 | AG21: 2 | AH21: 9 | AI21: 1 | AJ21: 0 | AK21: 15 | AL21: South Africa | AM21: 229 Runs | AN21: Heinrich Klaasen | AO21: Nitin Menon | AP21: Kumar Dharmasena | AQ21: Paul Reiffel | AR21: Javagal Srinath
A22: 21 | B22: 22/10/2023 | C22: 0.58333333 | D22: Dharamshala | E22: HPCA Stadium | F22: NewZealand | G22: India | H22: India | I22: Field | J22: 273 | K22: 10 | L22: 50 | M22: 0 | N22: 19 | O22: 7 | P22: 26 | Q22: 5.46 | R22: 1 | S22: 0 | T22: 4 | U22: 0 | V22: 0 | W22: 5 | X22: 274 | Y22: 6 | Z22: 48 | AA22: 2 | AB22: 29 | AC22: 7 | AD22: 36 | AE22: 5.7 | AF22: 5 | AG22: 3 | AH22: 7 | AI22: 0 | AJ22: 0 | AK22: 15 | AL22: India | AM22: 4 Wickets | AN22: Mohammed Shami | AO22: Richard Kettleborough | AP22: Michael Gough | AQ22: Paul Wilson | AR22: Andy Pycroft
A23: 22 | B23: 23/10/2023 | C23: 0.58333333 | D23: Chennai | E23: M. A. Chidambaram Stadium | F23: Pakistan | G23: Afghanistan | H23: Pakistan | I23: Bat | J23: 282 | K23: 7 | L23: 50 | M23: 2 | N23: 17 | O23: 9 | P23: 26 | Q23: 5.64 | R23: 0 | S23: 0 | T23: 8 | U23: 1 | V23: 0 | W23: 9 | X23: 286 | Y23: 2 | Z23: 49 | AA23: 0 | AB23: 28 | AC23: 3 | AD23: 31 | AE23: 5.83 | AF23: 4 | AG23: 0 | AH23: 12 | AI23: 1 | AJ23: 0 | AK23: 17 | AL23: Afghanistan | AM23: 8 Wickets | AN23: Ibrahim Zadran | AO23: Paul Reiffel | AP23: Rod Tucker | AQ23: Chris Gaffaney | AR23: Richie Richardson
... A32: 31 | B32: 31/10/2023 | C32: 0.58333333 | D32: Kolkata | E32: Eden Gardens | F32: Bangladesh | G32: Pakistan | H32: Bangladesh | I32: Bat | J32: 205 | K32: 3 | L32: 32.3 | M32: 2 | N32: 19 | O32: 3 | P32: 22 | Q32: 6.3 | R32: 2 | S32: 0 | T32: 2 | U32: 0 | V32: 0 | W32: 4 | X32: 204 | Y32: 10 | Z32: 45.1 | AA32: 2 | AB32: 19 | AC32: 9 | AD32: 28 | AE32: 4.51 | AF32: 4 | AG32: 0 | AH32: 5 | AI32: 0 | AJ32: 0 | AK32: 9 | AL32: Pakistan | AM32: 7 Wickets | AN32: Fakhar Zaman | AO32: Richard Kettleborough | AP32: Nitin Menon | AQ32: Adrian Holdstock | AR32: Andy Pycroft
A33: 32 | B33: 44937 | C33: 0.58333333 | D33: Pune | E33: Maharashtra Cricket Association Stadium | F33: South Africa | G33: NewZealand | H33: NewZealand | I33: Field | J33: 357 | K33: 4 | L33: 50 | M33: 4 | N33: 26 | O33: 15 | P33: 41 | Q33: 7.14 | R33: 1 | S33: 4 | T33: 6 | U33: 1 | V33: 0 | W33: 12 | X33: 167 | Y33: 10 | Z33: 35.3 | AA33: 1 | AB33: 17 | AC33: 4 | AD33: 21 | AE33: 4.7 | AF33: 4 | AG33: 0 | AH33: 8 | AI33: 0 | AJ33: 0 | AK33: 12 | AL33: South Africa | AM33: 190 Runs | AN33: Rassie van der Dussen | AO33: Kumar Dharmasena | AP33: Ahsan Raza | AQ33: Sharfuddoula | AR33: Richie Richardson
A34: 33 | B34: 44968 | C34: 0.58333333 | D34: Mumbai | E34: Wankhede Stadium | F34: India | G34: Sri Lanka | H34: Sri Lanka | I34: Field | J34: 357 | K34: 8 | L34: 50 | M34: 4 | N34: 31 | O34: 9 | P34: 40 | Q34: 7.14 | R34: 1 | S34: 5 | T34: 4 | U34: 0 | V34: 0 | W34: 10 | X34: 55 | Y34: 10 | Z34: 19.4 | AA34: 2 | AB34: 6 | AC34: 0 | AD34: 6 | AE34: 2.79 | AF34: 6 | AG34: 5 | AH34: 8 | AI34: 1 | AJ34: 0 | AK34: 20 | AL34: India | AM34: 302 Runs | AN34: Mohammed Shami | AO34: Chris Brown | AP34: Paul Reiffel | AQ34: Rod Tucker | AR34: Jeff Crowe
A35: 34 | B35: 44996 | C35: 0.4375 | D35: Lucknow | E35: BRSABV Ekana Cricket Stadium | F35: Netherlands | G35: Afghanistan | H35: Netherlands | I35: Bat | J35: 181 | K35: 3 | L35: 31.3 | M35: 0 | N35: 19 | O35: 0 | P35: 19 | Q35: 5.74 | R35: 3 | S35: 0 | T35: 7 | U35: 2 | V35: 0 | W35: 12 | X35: 179 | Y35: 10 | Z35: 46.3 | AA35: 1 | AB35: 21 | AC35: 0 | AD35: 21 | AE35: 3.84 | AF35: 2 | AG35: 0 | AH35: 14 | AI35: 0 | AJ35: 0 | AK35: 16 | AL35: Afghanistan | AM35: 7 Wickets | AN35: Mohammad Nabi | AO35: Nitin Menon | AP35: Sharfuddoula | AQ35: Michael Gough | AR35: Javagal Srinath
A36: 35 | B36: 45027 | C36: 0.58333333 | D36: Bangalore | E36: M. Chinnaswamy Stadium | F36: NewZealand | G36: Pakistan | H36: Pakistan | I36: Field | J36: 401 | K36: 6 | L36: 50 | M36: 1 | N36: 46 | O36: 8 | P36: 54 | Q36: 8.02 | R36: 1 | S36: 0 | T36: 3 | U36: 0 | V36: 0 | W36: 4 | X36: 200 | Y36: 1 | Z36: 25.3 | AA36: 0 | AB36: 15 | AC36: 13 | AD36: 28 | AE36: 7.84 | AF36: 8 | AG36: 0 | AH36: 17 | AI36: 1 | AJ36: 0 | AK36: 26 | AL36: Pakistan | AM36: 21 Runs DLS Method | AN36: Fakhar Zaman | AO36: Paul Wilson | AP36: Richard Kettleborough | AQ36: Richard Illingworth | AR36: Richie Richardson
A37: 36 | B37: 45027 | C37: 0.58333333 | D37: Ahmedabad | E37: Narendra Modi Stadium | F37: Australia | G37: England | H37: England | I37: Field | J37: 286 | K37: 10 | L37: 49.3 | M37: 2 | N37: 25 | O37: 3 | P37: 28 | Q37: 5.77 | R37: 6 | S37: 0 | T37: 8 | U37: 0 | V37: 0 | W37: 14 | X37: 253 | Y37: 10 | Z37: 48.1 | AA37: 1 | AB37: 22 | AC37: 6 | AD37: 28 | AE37: 5.25 | AF37: 6 | AG37: 0 | AH37: 4 | AI37: 0 | AJ37: 0 | AK37: 10 | AL37: Australia | AM37: 33 Runs | AN37: Adam Zampa | AO37: Chris Gaffaney | AP37: Marais Erasmus | AQ37: Adrian Holdstock | AR37: Jeff Crowe
A38: 37 | B38: 45057 | C38: 0.58333333 | D38: Kolkata | E38: Eden Gardens | F38: India | G38: South Africa | H38: India | I38: Bat | J38: 326 | K38: 5 | L38: 50 | M38: 3 | N38: 35 | O38: 6 | P38: 41 | Q38: 6.52 | R38: 0 | S38: 0 | T38: 2 | U38: 0 | V38: 0 | W38: 2 | X38: 83 | Y38: 10 | Z38: 27.1 | AA38: 1 | AB38: 10 | AC38: 0 | AD38: 10 | AE38: 3.05 | AF38: 2 | AG38: 0 | AH38: 22 | AI38: 2 | AJ38: 0 | AK38: 26 | AL38: India | AM38: 243 Runs | AN38: Virat Kohli | AO38: Paul Reiffel | AP38: Kumar Dharmasena | AQ38: Chris Brown | AR38: Andy Pycroft
A39: 38 | B39: 45088 | C39: 0.58333333 | D39: Delhi | E39: Arun Jaitley Stadium | F39: Sri Lanka | G39: Bangladesh | H39: Bangladesh | I39: Field | J39: 279 | K39: 10 | L39: 49.3 | M39: 2 | N39: 27 | O39: 7 | P39: 34 | Q39: 5.63 | R39: 13 | S39: 0 | T39: 10 | U39: 0 | V39: 0 | W39: 23 | X39: 282 | Y39: 7 | Z39: 41.1 | AA39: 1 | AB39: 33 | AC39: 7 | AD39: 40 | AE39: 6.85 | AF39: 2 | AG39: 0 | AH39: 4 | AI39: 0 | AJ39: 0 | AK39: 6 | AL39: Bangladesh | AM39: 3 Wickets | AN39: Shakib Al Hasan | AO39: Richard Illingworth | AP39: Marais Erasmus | AQ39: Nitin Menon | AR39: Richie Richardson
A40: 39 | B40: 45118 | C40: 0.58333333 | D40: Mumbai | E40: Wankhede Stadium | F40: Australia | G40: Afghanistan | H40: Afghanistan | I40: Bat | J40: 293 | K40: 7 | L40: 46.5 | M40: 0 | N40: 30 | O40: 12 | P40: 42 | Q40: 6.25 | R40: 5 | S40: 0 | T40: 10 | U40: 1 | V40: 0 | W40: 16 | X40: 291 | Y40: 5 | Z40: 50 | AA40: 3 | AB40: 16 | AC40: 9 | AD40: 25 | AE40: 5.82 | AF40: 1 | AG40: 4 | AH40: 10 | AI40: 0 | AJ40: 0 | AK40: 15 | AL40: Australia | AM40: 3 Wickets | AN40: Glenn Maxwell | AO40: Michael Gough | AP40: Alex Wharf | AQ40: Chris Gaffaney | AR40: Jeff Crowe
A41: 40 | B41: 45149 | C41: 0.58333333 | D41: Pune | E41: Maharashtra Cricket Association Stadium | F41: England | G41: Netherlands | H41: England | I41: Bat | J41: 179 | K41: 10 | L41: 37.2 | M41: 2 | N41: 26 | O41: 10 | P41: 36 | Q41: 4.79 | R41: 4 | S41: 0 | T41: 4 | U41: 0 | V41: 0 | W41: 8 | X41: 339 | Y41: 9 | Z41: 50 | AA41: 0 | AB41: 15 | AC41: 6 | AD41: 21 | AE41: 6.78 | AF41: 0 | AG41: 0 | AH41: 20 | AI41: 1 | AJ41: 0 | AK41: 21 | AL41: England | AM41: 160 Runs | AN41: Ben Stokes | AO41: Ahsan Raza | AP41: Rod Tucker | AQ41: Marais Erasmus | AR41: Andy Pycroft
A42: 41 | B42: 45180 | C42: 0.58333333 | D42: Bangalore | E42: M. Chinnaswamy Stadium | F42: NewZealand | G42: Sri Lanka | H42: NewZealand | I42: Field | J42: 171 | K42: 10 | L42: 46.4 | M42: 7 | N42: 23 | O42: 5 | P42: 28 | Q42: 3.66 | R42: 1 | S42: 0 | T42: 3 | U42: 0 | V42: 0 | W42: 4 | X42: 172 | Y42: 5 | Z42: 23.2 | AA42: 1 | AB42: 21 | AC42: 3 | AD42: 24 | AE42: 7.37 | AF42: 0 | AG42: 0 | AH42: 2 | AI42: 0 | AJ42: 0 | AK42: 2 | AL42: NewZealand | AM42: 5 Wickets | AN42: Trent Boult | AO42: Adrian Holdstock | AP42: Joel Wilson | AQ42: Richard Kettleborough | AR42: Javagal Srinath
A43: 42 | B43: 45210 | C43: 0.4375 | D43: Ahmedabad | E43: Narendra Modi Stadium | F43: Afghanistan | G43: South Africa | H43: Afghanistan | I43: Bat | J43: 244 | K43: 10 | L43: 50 | M43: 2 | N43: 20 | O43: 6 | P43: 26 | Q43: 4.88 | R43: 3 | S43: 0 | T43: 6 | U43: 0 | V43: 0 | W43: 9 | X43: 247 | Y43: 5 | Z43: 47.3 | AA43: 2 | AB43: 15 | AC43: 9 | AD43: 24 | AE43: 5.2 | AF43: 1 | AG43: 4 | AH43: 10 | AI43: 0 | AJ43: 0 | AK43: 15 | AL43: South Africa | AM43: 5 Wickets | AN43: Rassie van der Dussen | AO43: Nitin Menon | AP43: Chris Brown | AQ43: Kumar Dharmasena | AR43: Jeff Crowe
A44: 43 | B44: 45241 | C44: 0.58333333 | D44: Pune | E44: Maharashtra Cricket Association Stadium | F44: Australia | G44: Bangladesh | H44: Australia | I44: Field | J44: 306 | K44: 8 | L44: 50 | M44: 1 | N44: 29 | O44: 10 | P44: 39 | Q44: 6.12 | R44: 10 | S44: 0 | T44: 12 | U44: 2 | V44: 0 | W44: 24 | X44: 307 | Y44: 2 | Z44: 44.4 | AA44: 1 | AB44: 27 | AC44: 6 | AD44: 33 | AE44: 6.87 | AF44: 0 | AG44: 0 | AH44: 4 | AI44: 0 | AJ44: 0 | AK44: 4 | AL44: Australia | AM44: 8 Wickets | AN44: Mitchell Marsh | AO44: Ahsan Raza | AP44: Marais Erasmus | AQ44: Richard Illingworth | AR44: Andy Pycroft
... A46: 45 | B46: 45271 | C46: 0.58333333 | D46: Bangalore | E46: M. Chinnaswamy Stadium | F46: India | G46: Netherlands | H46: India | I46: Bat | J46: 410 | K46: 4 | L46: 50 | M46: 3 | N46: 37 | O46: 16 | P46: 53 | Q46: 8.2 | R46: 9 | S46: 0 | T46: 4 | U46: 0 | V46: 0 | W46: 13 | X46: 250 | Y46: 10 | Z46: 47.5 | AA46: 0 | AB46: 19 | AC46: 9 | AD46: 28 | AE46: 5.22 | AF46: 1 | AG46: 0 | AH46: 13 | AI46: 1 | AJ46: 0 | AK46: 15 | AL46: India | AM46: 160 Runs | AN46: Shreyas Iyer | AO46: Michael Gough | AP46: Chris Gaffaney | AQ46: Joel Wilson | AR46: Richie Richardson
A47: 46 | B47: 15/11/2023 | C47: 0.58333333 | D47: Mumbai | E47: Wankhede Stadium | F47: India | G47: NewZealand | H47: India | I47: Bat | J47: 397 | K47: 4 | L47: 50 | M47: 1 | N47: 30 | O47: 19 | P47: 49 | Q47: 7.94 | R47: 5 | S47: 4 | T47: 19 | U47: 1 | V47: 0 | W47: 29 | X47: 327 | Y47: 10 | Z47: 48.5 | AA47: 1 | AB47: 29 | AC47: 11 | AD47: 40 | AE47: 6.69 | AF47: 1 | AG47: 1 | AH47: 6 | AI47: 0 | AJ47: 0 | AK47: 8 | AL47: India | AM47: 70 Runs | AN47: Mohammed Shami | AO47: Richard Illingworth | AP47: Rod Tucker | AQ47: Joel Wilson | AR47: Andy Pycroft
A48: 47 | B48: 16/11/2023 | C48: 0.58333333 | D48: Kolkata | E48: Eden Gardens | F48: Australia | G48: South Africa | H48: South Africa | I48: Bat | J48: 215 | K48: 7 | L48: 47.2 | M48: 4 | N48: 21 | O48: 6 | P48: 27 | Q48: 4.54 | R48: 4 | S48: 0 | T48: 7 | U48: 0 | V48: 0 | W48: 11 | X48: 212 | Y48: 10 | Z48: 49.4 | AA48: 1 | AB48: 16 | AC48: 8 | AD48: 24 | AE48: 4.26 | AF48: 3 | AG48: 0 | AH48: 12 | AI48: 2 | AJ48: 0 | AK48: 17 | AL48: Australia | AM48: 3 Wickets | AN48: Travis Head | AO48: Nitin Menon | AP48: Richard Kettleborough | AQ48: Chris Gaffaney | AR48: Javagal Srinath
A49: 48 | B49: 19/11/2023 | C49: 0.58333333 | D49: Ahmedabad | E49: Narendra Modi Stadium | F49: India | G49: Australia | H49: Australia | I49: Field | J49: 240 | K49: 10 | L49: 50 | M49: 3 | N49: 13 | O49: 3 | P49: 16 | Q49: 4.8 | R49: 2 | S49: 5 | T49: 11 | U49: 0 | V49: 0 | W49: 18 | X49: 241 | Y49: 4 | Z49: 43 | AA49: 0 | AB49: 22 | AC49: 5 | AD49: 27 | AE49: 5.6 | AF49: 3 | AG49: 0 | AH49: 9 | AI49: 0 | AJ49: 0 | AK49: 12 | AL49: Australia | AM49: 6 Wickets | AN49: Travis Head | AO49: Richard Illingworth | AP49: Richard Kettleborough | AQ49: Joel Wilson | AR49: Andy Pycroft

Sheet Calculations
A1: Match ID | B1: Match Date | C1: City | D1: Stadium | E1: Team A | F1: Team B | G1: Toss Winner | H1: Winning Team | I1: Toss Decision | J1: Score A | K1: Score B | L1: Total Runs (match) | M1: Total Wickets (match) | N1: Total 4s (match) | O1: Total 6s (match) | P1: Total Boundaries (match) | Q1: Margin (text) | R1: Margin Value | S1: Winning Margin Type | T1: Match Result | U1: Toss Winner Won Match (1/0) | V1: Match Result by Toss | W1: Man of the Match | X1: Winning Runs Range | Y1: Winning Wickets Range | AA1: Match ID | AB1: Match Date | AC1: Team | AD1: Opponent | AE1: City | AF1: Stadium | AG1: Winning Margin Type | AH1: Match Result | AI1: Score | AJ1: Wickets Taken (bowling) | AK1: Wickets Lost (batting) | AL1: Overs Played | AM1: Maiden Overs | AN1: 4s | AO1: 6s | AP1: Total Boundaries (4s+6s) | AQ1: Runrate | AR1: Winning Team | AS1: Byes | AT1: Wides | AU1: No Balls | AV1: Extras | AW1: Match Played | AX1: Win(1/0) | AY1: Loss(1/0) | AZ1: Win/Loss | BA1: Toss Won (1/0) | BB1: Toss Won & Match Won | BC1: Toss Decision
A2: 1 | B2: =IF(ISNUMBER(Table1[[#This Row],[Match Date]]),DATE(YEAR(Table1[[#This Row],[Match Date]]),DAY(Table1[[#This Row],[Match Date]]),MONTH(Table1[[#This Row],[Match Date]])),DATE(VALUE(RIGHT(TRIM(Table1[[#This Row],[Match Date]]),4)),VALUE(MID(TRIM(Table1[[#This Row],[Match Date]]),4,2)),VALUE(LEFT(TRIM(Table1[[#This Row],[Match Date]]),2)))) -> 45204 | C2: =TRIM(Table1[[#This Row],[City]]) -> Ahmedabad | D2: =IF(AND(TRIM(Table1[[#This Row],[Stadium]])="Eden Gardens",TRIM(Table1[[#This Row],[City]])<>"Kolkata"),"Rajiv Gandhi International Stadium",TRIM(Table1[[#This Row],[Stadium]])) -> Narendra Modi Stadium | E2: =SUBSTITUTE(Table1[[#This Row],[Team A]],"NewZealand","New Zealand") -> England | F2: =SUBSTITUTE(Table1[[#This Row],[Team B]],"NewZealand","New Zealand") -> New Zealand | G2: =SUBSTITUTE(Table1[[#This Row],[Toss Winner]],"NewZealand","New Zealand") -> New Zealand | H2: =SUBSTITUTE(Table1[[#This Row],[Wining Team]],"NewZealand","New Zealand") -> New Zealand | I2: =TRIM(Table1[[#This Row],[Toss Decision]]) -> Field | J2: =Table1[[#This Row],[Score A]] -> 282 | K2: =Table1[[#This Row],[Score B]] -> 283 | L2: =SUM(Calculations_1[[#This Row],[Score A]],Calculations_1[[#This Row],[Score B]]) -> 565 | M2: =SUM(Table1[[#This Row],[Wickets A]],Table1[[#This Row],[Wickets B]]) -> 10 | N2: =SUM(Table1[[#This Row],[4s A]],Table1[[#This Row],[4s B]]) -> 51 | O2: =SUM(Table1[[#This Row],[6s A]],Table1[[#This Row],[6s B]]) -> 14 | P2: =SUM(Calculations_1[[#This Row],[Total 4s (match)]],Calculations_1[[#This Row],[Total 6s (match)]]) -> 65 | Q2: =TRIM(Table1[[#This Row],[Margin]]) -> 9 Wickets | R2: =VALUE(LEFT(Calculations_1[[#This Row],[Margin (text)]],FIND(" ",Calculations_1[[#This Row],[Margin (text)]])-1)) -> 9 | S2: =IF(ISNUMBER(SEARCH("DLS",Calculations_1[[#This Row],[Margin (text)]])),"Runs (DLS) Method",IF(ISNUMBER(SEARCH("run",Calculations_1[[#This Row],[Margin (text)]])),"Runs","Wickets")) -> Wickets | T2: =IF(Calculations_1[[#This Row],[Winning Margin Type]]="Wickets","Chasing Won",IF(Calculations_1[[#This Row],[Winning Margin Type]]="Runs","Batting First Won","DLS Result")) -> Chasing Won | U2: =IF(Calculations_1[[#This Row],[Toss Winner]]=Calculations_1[[#This Row],[Winning Team]],1,0) -> 1 | V2: =IF(Calculations_1[[#This Row],[Toss Winner Won Match (1/0)]]=1,"Toss Winner Won","Toss Winner Lost") -> Toss Winner Won | W2: =TRIM(Table1[[#This Row],[Man of the Match]]) -> Rachin Ravindra | X2: {=IF(Calculations_1[[#This Row],[Winning Margin Type]]="Runs",_xlfn.IFS(Calculations_1[[#This Row],[Margin Value]]<=50,"1-50",Calculations_1[[#This Row],[Margin Value]]<=100,"51-100",Calculations_1[[#This Row],[Margin Value]]<=150,"101-150",Calculations_1[[#This Row],[Margin Value]]<=200,"151-200",TRUE,"201+"),"")} | Y2: {=IF(Calculations_1[[#This Row],[Winning Margin Type]]="Wickets",_xlfn.IFS(Calculations_1[[#This Row],[Margin Value]]<=3,"1-3",Calculations_1[[#This Row],[Margin Value]]<=6,"4-6",Calculations_1[[#This Row],[Margin Value]]<=10,"7-10"),"")} -> 7-10 | AA2: 1 | AB2: 45204 | AC2: England | AD2: New Zealand | AE2: Ahmedabad | AF2: Narendra Modi Stadium | AG2: Wickets | AH2: Chasing Won | AI2: 282 | AJ2: {=_xlfn.XLOOKUP( 1, (Table354[Match ID]=Table354[[#This Row],[Match ID]])* (Table354[Team]=Table354[[#This Row],[Opponent]]), Table354[Wickets Lost (batting)] )} -> 1 | AK2: 9 | AL2: 50 | AM2: 2 | AN2: 21 | AO2: 6 | AP2: 27 | AQ2: 5.64 | AR2: =_xlfn.XLOOKUP(Table354[[#This Row],[Match ID]],Calculations_1[Match ID],Calculations_1[Winning Team]) -> New Zealand | AS2: 4 | AT2: 3 | AU2: 0 | AV2: 8 | AW2: =1 -> 1 | AX2: =IF(Table354[[#This Row],[Team]]=_xlfn.XLOOKUP(Table354[[#This Row],[Match ID]],Calculations_1[Match ID],Calculations_1[Winning Team]),1,0) -> 0 | AY2: =IF(NOT(Table354[[#This Row],[Win(1/0)]]),1,0) -> 1 | AZ2: =IF(Table354[[#This Row],[Win(1/0)]]=1,"Win","Loss") -> Loss | BA2: =IF(Table354[[#This Row],[Team]]=_xlfn.XLOOKUP(Table354[[#This Row],[Match ID]],Calculations_1[Match ID],Calculations_1[Toss Winner]),1,0) -> 0 | BB2: =Table354[[#This Row],[Win(1/0)]]*Table354[[#This Row],[Toss Won (1/0)]] -> 0 | BC2: {=_xlfn.XLOOKUP(Table354[[#This Row],[Match ID]],Calculations_1[Match ID],Calculations_1[Toss Decision],NA,0)} -> Field
A3: 2 | B3: =IF(ISNUMBER(Table1[[#This Row],[Match Date]]),DATE(YEAR(Table1[[#This Row],[Match Date]]),DAY(Table1[[#This Row],[Match Date]]),MONTH(Table1[[#This Row],[Match Date]])),DATE(VALUE(RIGHT(TRIM(Table1[[#This Row],[Match Date]]),4)),VALUE(MID(TRIM(Table1[[#This Row],[Match Date]]),4,2)),VALUE(LEFT(TRIM(Table1[[#This Row],[Match Date]]),2)))) -> 45205 | C3: =TRIM(Table1[[#This Row],[City]]) -> Hyderabad | D3: =IF(AND(TRIM(Table1[[#This Row],[Stadium]])="Eden Gardens",TRIM(Table1[[#This Row],[City]])<>"Kolkata"),"Rajiv Gandhi International Stadium",TRIM(Table1[[#This Row],[Stadium]])) -> Rajiv Gandhi International Stadium | E3: =SUBSTITUTE(Table1[[#This Row],[Team A]],"NewZealand","New Zealand") -> Pakistan | F3: =SUBSTITUTE(Table1[[#This Row],[Team B]],"NewZealand","New Zealand") -> Netherlands | G3: =SUBSTITUTE(Table1[[#This Row],[Toss Winner]],"NewZealand","New Zealand") -> Netherlands | H3: =SUBSTITUTE(Table1[[#This Row],[Wining Team]],"NewZealand","New Zealand") -> Pakistan | I3: =TRIM(Table1[[#This Row],[Toss Decision]]) -> Field | J3: =Table1[[#This Row],[Score A]] -> 286 | K3: =Table1[[#This Row],[Score B]] -> 205 | L3: =SUM(Calculations_1[[#This Row],[Score A]],Calculations_1[[#This Row],[Score B]]) -> 491 | M3: =SUM(Table1[[#This Row],[Wickets A]],Table1[[#This Row],[Wickets B]]) -> 20 | N3: =SUM(Table1[[#This Row],[4s A]],Table1[[#This Row],[4s B]]) -> 53 | O3: =SUM(Table1[[#This Row],[6s A]],Table1[[#This Row],[6s B]]) -> 7 | P3: =SUM(Calculations_1[[#This Row],[Total 4s (match)]],Calculations_1[[#This Row],[Total 6s (match)]]) -> 60 | Q3: =TRIM(Table1[[#This Row],[Margin]]) -> 81 Runs | R3: =VALUE(LEFT(Calculations_1[[#This Row],[Margin (text)]],FIND(" ",Calculations_1[[#This Row],[Margin (text)]])-1)) -> 81 | S3: =IF(ISNUMBER(SEARCH("DLS",Calculations_1[[#This Row],[Margin (text)]])),"Runs (DLS) Method",IF(ISNUMBER(SEARCH("run",Calculations_1[[#This Row],[Margin (text)]])),"Runs","Wickets")) -> Runs | T3: =IF(Calculations_1[[#This Row],[Winning Margin Type]]="Wickets","Chasing Won",IF(Calculations_1[[#This Row],[Winning Margin Type]]="Runs","Batting First Won","DLS Result")) -> Batting First Won | U3: =IF(Calculations_1[[#This Row],[Toss Winner]]=Calculations_1[[#This Row],[Winning Team]],1,0) -> 0 | V3: =IF(Calculations_1[[#This Row],[Toss Winner Won Match (1/0)]]=1,"Toss Winner Won","Toss Winner Lost") -> Toss Winner Lost | W3: =TRIM(Table1[[#This Row],[Man of the Match]]) -> Saud Shakeel | X3: {=IF(Calculations_1[[#This Row],[Winning Margin Type]]="Runs",_xlfn.IFS(Calculations_1[[#This Row],[Margin Value]]<=50,"1-50",Calculations_1[[#This Row],[Margin Value]]<=100,"51-100",Calculations_1[[#This Row],[Margin Value]]<=150,"101-150",Calculations_1[[#This Row],[Margin Value]]<=200,"151-200",TRUE,"201+"),"")} -> 51-100 | Y3: {=IF(Calculations_1[[#This Row],[Winning Margin Type]]="Wickets",_xlfn.IFS(Calculations_1[[#This Row],[Margin Value]]<=3,"1-3",Calculations_1[[#This Row],[Margin Value]]<=6,"4-6",Calculations_1[[#This Row],[Margin Value]]<=10,"7-10"),"")} | AA3: 1 | AB3: 45204 | AC3: New Zealand | AD3: England | AE3: Ahmedabad | AF3: Narendra Modi Stadium | AG3: Wickets | AH3: Chasing Won | AI3: 283 | AJ3: {=_xlfn.XLOOKUP( 1, (Table354[Match ID]=Table354[[#This Row],[Match ID]])* (Table354[Team]=Table354[[#This Row],[Opponent]]), Table354[Wickets Lost (batting)] )} -> 9 | AK3: 1 | AL3: 36.2 | AM3: 2 | AN3: 30 | AO3: 8 | AP3: 38 | AQ3: 7.78 | AR3: =_xlfn.XLOOKUP(Table354[[#This Row],[Match ID]],Calculations_1[Match ID],Calculations_1[Winning Team]) -> New Zealand | AS3: 0 | AT3: 6 | AU3: 0 | AV3: 6 | AW3: =1 -> 1 | AX3: =IF(Table354[[#This Row],[Team]]=_xlfn.XLOOKUP(Table354[[#This Row],[Match ID]],Calculations_1[Match ID],Calculations_1[Winning Team]),1,0) -> 1 | AY3: =IF(NOT(Table354[[#This Row],[Win(1/0)]]),1,0) -> 0 | AZ3: =IF(Table354[[#This Row],[Win(1/0)]]=1,"Win","Loss") -> Win | BA3: =IF(Table354[[#This Row],[Team]]=_xlfn.XLOOKUP(Table354[[#This Row],[Match ID]],Calculations_1[Match ID],Calculations_1[Toss Winner]),1,0) -> 1 | BB3: =Table354[[#This Row],[Win(1/0)]]*Table354[[#This Row],[Toss Won (1/0)]] -> 1 | BC3: {=_xlfn.XLOOKUP(Table354[[#This Row],[Match ID]],Calculations_1[Match ID],Calculations_1[Toss Decision],NA,0)} -> Field
A4: 3 | B4: =IF(ISNUMBER(Table1[[#This Row],[Match Date]]),DATE(YEAR(Table1[[#This Row],[Match Date]]),DAY(Table1[[#This Row],[Match Date]]),MONTH(Table1[[#This Row],[Match Date]])),DATE(VALUE(RIGHT(TRIM(Table1[[#This Row],[Match Date]]),4)),VALUE(MID(TRIM(Table1[[#This Row],[Match Date]]),4,2)),VALUE(LEFT(TRIM(Table1[[#This Row],[Match Date]]),2)))) -> 45206 | C4: =TRIM(Table1[[#This Row],[City]]) -> Dharamshala | D4: =IF(AND(TRIM(Table1[[#This Row],[Stadium]])="Eden Gardens",TRIM(Table1[[#This Row],[City]])<>"Kolkata"),"Rajiv Gandhi International Stadium",TRIM(Table1[[#This Row],[Stadium]])) -> HPCA Stadium | E4: =SUBSTITUTE(Table1[[#This Row],[Team A]],"NewZealand","New Zealand") -> Afghanistan | F4: =SUBSTITUTE(Table1[[#This Row],[Team B]],"NewZealand","New Zealand") -> Bangladesh | G4: =SUBSTITUTE(Table1[[#This Row],[Toss Winner]],"NewZealand","New Zealand") -> Bangladesh | H4: =SUBSTITUTE(Table1[[#This Row],[Wining Team]],"NewZealand","New Zealand") -> Bangladesh | I4: =TRIM(Table1[[#This Row],[Toss Decision]]) -> Field | J4: =Table1[[#This Row],[Score A]] -> 156 | K4: =Table1[[#This Row],[Score B]] -> 158 | L4: =SUM(Calculations_1[[#This Row],[Score A]],Calculations_1[[#This Row],[Score B]]) -> 314 | M4: =SUM(Table1[[#This Row],[Wickets A]],Table1[[#This Row],[Wickets B]]) -> 14 | N4: =SUM(Table1[[#This Row],[4s A]],Table1[[#This Row],[4s B]]) -> 28 | O4: =SUM(Table1[[#This Row],[6s A]],Table1[[#This Row],[6s B]]) -> 3 | P4: =SUM(Calculations_1[[#This Row],[Total 4s (match)]],Calculations_1[[#This Row],[Total 6s (match)]]) -> 31 | Q4: =TRIM(Table1[[#This Row],[Margin]]) -> 6 Wickets | R4: =VALUE(LEFT(Calculations_1[[#This Row],[Margin (text)]],FIND(" ",Calculations_1[[#This Row],[Margin (text)]])-1)) -> 6 | S4: =IF(ISNUMBER(SEARCH("DLS",Calculations_1[[#This Row],[Margin (text)]])),"Runs (DLS) Method",IF(ISNUMBER(SEARCH("run",Calculations_1[[#This Row],[Margin (text)]])),"Runs","Wickets")) -> Wickets | T4: =IF(Calculations_1[[#This Row],[Winning Margin Type]]="Wickets","Chasing Won",IF(Calculations_1[[#This Row],[Winning Margin Type]]="Runs","Batting First Won","DLS Result")) -> Chasing Won | U4: =IF(Calculations_1[[#This Row],[Toss Winner]]=Calculations_1[[#This Row],[Winning Team]],1,0) -> 1 | V4: =IF(Calculations_1[[#This Row],[Toss Winner Won Match (1/0)]]=1,"Toss Winner Won","Toss Winner Lost") -> Toss Winner Won | W4: =TRIM(Table1[[#This Row],[Man of the Match]]) -> Mehidy Hasan Miraz | X4: {=IF(Calculations_1[[#This Row],[Winning Margin Type]]="Runs",_xlfn.IFS(Calculations_1[[#This Row],[Margin Value]]<=50,"1-50",Calculations_1[[#This Row],[Margin Value]]<=100,"51-100",Calculations_1[[#This Row],[Margin Value]]<=150,"101-150",Calculations_1[[#This Row],[Margin Value]]<=200,"151-200",TRUE,"201+"),"")} | Y4: {=IF(Calculations_1[[#This Row],[Winning Margin Type]]="Wickets",_xlfn.IFS(Calculations_1[[#This Row],[Margin Value]]<=3,"1-3",Calculations_1[[#This Row],[Margin Value]]<=6,"4-6",Calculations_1[[#This Row],[Margin Value]]<=10,"7-10"),"")} -> 4-6 | AA4: 2 | AB4: 45205 | AC4: Pakistan | AD4: Netherlands | AE4: Hyderabad | AF4: Rajiv Gandhi International Stadium | AG4: Runs | AH4: Batting First Won | AI4: 286 | AJ4: {=_xlfn.XLOOKUP( 1, (Table354[Match ID]=Table354[[#This Row],[Match ID]])* (Table354[Team]=Table354[[#This Row],[Opponent]]), Table354[Wickets Lost (batting)] )} -> 10 | AK4: 10 | AL4: 49 | AM4: 1 | AN4: 33 | AO4: 3 | AP4: 36 | AQ4: 5.83 | AR4: =_xlfn.XLOOKUP(Table354[[#This Row],[Match ID]],Calculations_1[Match ID],Calculations_1[Winning Team]) -> Pakistan | AS4: 0 | AT4: 9 | AU4: 0 | AV4: 9 | AW4: =1 -> 1 | AX4: =IF(Table354[[#This Row],[Team]]=_xlfn.XLOOKUP(Table354[[#This Row],[Match ID]],Calculations_1[Match ID],Calculations_1[Winning Team]),1,0) -> 1 | AY4: =IF(NOT(Table354[[#This Row],[Win(1/0)]]),1,0) -> 0 | AZ4: =IF(Table354[[#This Row],[Win(1/0)]]=1,"Win","Loss") -> Win | BA4: =IF(Table354[[#This Row],[Team]]=_xlfn.XLOOKUP(Table354[[#This Row],[Match ID]],Calculations_1[Match ID],Calculations_1[Toss Winner]),1,0) -> 0 | BB4: =Table354[[#This Row],[Win(1/0)]]*Table354[[#This Row],[Toss Won (1/0)]] -> 0 | BC4: {=_xlfn.XLOOKUP(Table354[[#This Row],[Match ID]],Calculations_1[Match ID],Calculations_1[Toss Decision],NA,0)} -> Field
A5: 4 | B5: =IF(ISNUMBER(Table1[[#This Row],[Match Date]]),DATE(YEAR(Table1[[#This Row],[Match Date]]),DAY(Table1[[#This Row],[Match Date]]),MONTH(Table1[[#This Row],[Match Date]])),DATE(VALUE(RIGHT(TRIM(Table1[[#This Row],[Match Date]]),4)),VALUE(MID(TRIM(Table1[[#This Row],[Match Date]]),4,2)),VALUE(LEFT(TRIM(Table1[[#This Row],[Match Date]]),2)))) -> 45206 | C5: =TRIM(Table1[[#This Row],[City]]) -> Delhi | D5: =IF(AND(TRIM(Table1[[#This Row],[Stadium]])="Eden Gardens",TRIM(Table1[[#This Row],[City]])<>"Kolkata"),"Rajiv Gandhi International Stadium",TRIM(Table1[[#This Row],[Stadium]])) -> Arun Jaitley Stadium | E5: =SUBSTITUTE(Table1[[#This Row],[Team A]],"NewZealand","New Zealand") -> South Africa | F5: =SUBSTITUTE(Table1[[#This Row],[Team B]],"NewZealand","New Zealand") -> Sri Lanka | G5: =SUBSTITUTE(Table1[[#This Row],[Toss Winner]],"NewZealand","New Zealand") -> Sri Lanka | H5: =SUBSTITUTE(Table1[[#This Row],[Wining Team]],"NewZealand","New Zealand") -> South Africa | I5: =TRIM(Table1[[#This Row],[Toss Decision]]) -> Field | J5: =Table1[[#This Row],[Score A]] -> 428 | K5: =Table1[[#This Row],[Score B]] -> 326 | L5: =SUM(Calculations_1[[#This Row],[Score A]],Calculations_1[[#This Row],[Score B]]) -> 754 | M5: =SUM(Table1[[#This Row],[Wickets A]],Table1[[#This Row],[Wickets B]]) -> 15 | N5: =SUM(Table1[[#This Row],[4s A]],Table1[[#This Row],[4s B]]) -> 76 | O5: =SUM(Table1[[#This Row],[6s A]],Table1[[#This Row],[6s B]]) -> 31 | P5: =SUM(Calculations_1[[#This Row],[Total 4s (match)]],Calculations_1[[#This Row],[Total 6s (match)]]) -> 107 | Q5: =TRIM(Table1[[#This Row],[Margin]]) -> 102 Runs | R5: =VALUE(LEFT(Calculations_1[[#This Row],[Margin (text)]],FIND(" ",Calculations_1[[#This Row],[Margin (text)]])-1)) -> 102 | S5: =IF(ISNUMBER(SEARCH("DLS",Calculations_1[[#This Row],[Margin (text)]])),"Runs (DLS) Method",IF(ISNUMBER(SEARCH("run",Calculations_1[[#This Row],[Margin (text)]])),"Runs","Wickets")) -> Runs | T5: =IF(Calculations_1[[#This Row],[Winning Margin Type]]="Wickets","Chasing Won",IF(Calculations_1[[#This Row],[Winning Margin Type]]="Runs","Batting First Won","DLS Result")) -> Batting First Won | U5: =IF(Calculations_1[[#This Row],[Toss Winner]]=Calculations_1[[#This Row],[Winning Team]],1,0) -> 0 | V5: =IF(Calculations_1[[#This Row],[Toss Winner Won Match (1/0)]]=1,"Toss Winner Won","Toss Winner Lost") -> Toss Winner Lost | W5: =TRIM(Table1[[#This Row],[Man of the Match]]) -> Aiden Markram | X5: {=IF(Calculations_1[[#This Row],[Winning Margin Type]]="Runs",_xlfn.IFS(Calculations_1[[#This Row],[Margin Value]]<=50,"1-50",Calculations_1[[#This Row],[Margin Value]]<=100,"51-100",Calculations_1[[#This Row],[Margin Value]]<=150,"101-150",Calculations_1[[#This Row],[Margin Value]]<=200,"151-200",TRUE,"201+"),"")} -> 101-150 | Y5: {=IF(Calculations_1[[#This Row],[Winning Margin Type]]="Wickets",_xlfn.IFS(Calculations_1[[#This Row],[Margin Value]]<=3,"1-3",Calculations_1[[#This Row],[Margin Value]]<=6,"4-6",Calculations_1[[#This Row],[Margin Value]]<=10,"7-10"),"")} | AA5: 2 | AB5: 45205 | AC5: Netherlands | AD5: Pakistan | AE5: Hyderabad | AF5: Rajiv Gandhi International Stadium | AG5: Runs | AH5: Batting First Won | AI5: 205 | AJ5: {=_xlfn.XLOOKUP( 1, (Table354[Match ID]=Table354[[#This Row],[Match ID]])* (Table354[Team]=Table354[[#This Row],[Opponent]]), Table354[Wickets Lost (batting)] )} -> 10 | AK5: 10 | AL5: 41 | AM5: 1 | AN5: 20 | AO5: 4 | AP5: 24 | AQ5: 5 | AR5: =_xlfn.XLOOKUP(Table354[[#This Row],[Match ID]],Calculations_1[Match ID],Calculations_1[Winning Team]) -> Pakistan | AS5: 0 | AT5: 8 | AU5: 1 | AV5: 9 | AW5: =1 -> 1 | AX5: =IF(Table354[[#This Row],[Team]]=_xlfn.XLOOKUP(Table354[[#This Row],[Match ID]],Calculations_1[Match ID],Calculations_1[Winning Team]),1,0) -> 0 | AY5: =IF(NOT(Table354[[#This Row],[Win(1/0)]]),1,0) -> 1 | AZ5: =IF(Table354[[#This Row],[Win(1/0)]]=1,"Win","Loss") -> Loss | BA5: =IF(Table354[[#This Row],[Team]]=_xlfn.XLOOKUP(Table354[[#This Row],[Match ID]],Calculations_1[Match ID],Calculations_1[Toss Winner]),1,0) -> 1 | BB5: =Table354[[#This Row],[Win(1/0)]]*Table354[[#This Row],[Toss Won (1/0)]] -> 0 | BC5: {=_xlfn.XLOOKUP(Table354[[#This Row],[Match ID]],Calculations_1[Match ID],Calculations_1[Toss Decision],NA,0)} -> Field
A6: 5 | B6: =IF(ISNUMBER(Table1[[#This Row],[Match Date]]),DATE(YEAR(Table1[[#This Row],[Match Date]]),DAY(Table1[[#This Row],[Match Date]]),MONTH(Table1[[#This Row],[Match Date]])),DATE(VALUE(RIGHT(TRIM(Table1[[#This Row],[Match Date]]),4)),VALUE(MID(TRIM(Table1[[#This Row],[Match Date]]),4,2)),VALUE(LEFT(TRIM(Table1[[#This Row],[Match Date]]),2)))) -> 45207 | C6: =TRIM(Table1[[#This Row],[City]]) -> Chennai | D6: =IF(AND(TRIM(Table1[[#This Row],[Stadium]])="Eden Gardens",TRIM(Table1[[#This Row],[City]])<>"Kolkata"),"Rajiv Gandhi International Stadium",TRIM(Table1[[#This Row],[Stadium]])) -> M. A. Chidambaram Stadium | E6: =SUBSTITUTE(Table1[[#This Row],[Team A]],"NewZealand","New Zealand") -> Australia | F6: =SUBSTITUTE(Table1[[#This Row],[Team B]],"NewZealand","New Zealand") -> India | G6: =SUBSTITUTE(Table1[[#This Row],[Toss Winner]],"NewZealand","New Zealand") -> Australia | H6: =SUBSTITUTE(Table1[[#This Row],[Wining Team]],"NewZealand","New Zealand") -> India | I6: =TRIM(Table1[[#This Row],[Toss Decision]]) -> Bat | J6: =Table1[[#This Row],[Score A]] -> 199 | K6: =Table1[[#This Row],[Score B]] -> 201 | L6: =SUM(Calculations_1[[#This Row],[Score A]],Calculations_1[[#This Row],[Score B]]) -> 400 | M6: =SUM(Table1[[#This Row],[Wickets A]],Table1[[#This Row],[Wickets B]]) -> 14 | N6: =SUM(Table1[[#This Row],[4s A]],Table1[[#This Row],[4s B]]) -> 30 | O6: =SUM(Table1[[#This Row],[6s A]],Table1[[#This Row],[6s B]]) -> 5 | P6: =SUM(Calculations_1[[#This Row],[Total 4s (match)]],Calculations_1[[#This Row],[Total 6s (match)]]) -> 35 | Q6: =TRIM(Table1[[#This Row],[Margin]]) -> 6 wickets | R6: =VALUE(LEFT(Calculations_1[[#This Row],[Margin (text)]],FIND(" ",Calculations_1[[#This Row],[Margin (text)]])-1)) -> 6 | S6: =IF(ISNUMBER(SEARCH("DLS",Calculations_1[[#This Row],[Margin (text)]])),"Runs (DLS) Method",IF(ISNUMBER(SEARCH("run",Calculations_1[[#This Row],[Margin (text)]])),"Runs","Wickets")) -> Wickets | T6: =IF(Calculations_1[[#This Row],[Winning Margin Type]]="Wickets","Chasing Won",IF(Calculations_1[[#This Row],[Winning Margin Type]]="Runs","Batting First Won","DLS Result")) -> Chasing Won | U6: =IF(Calculations_1[[#This Row],[Toss Winner]]=Calculations_1[[#This Row],[Winning Team]],1,0) -> 0 | V6: =IF(Calculations_1[[#This Row],[Toss Winner Won Match (1/0)]]=1,"Toss Winner Won","Toss Winner Lost") -> Toss Winner Lost | W6: =TRIM(Table1[[#This Row],[Man of the Match]]) -> KL Rahul | X6: {=IF(Calculations_1[[#This Row],[Winning Margin Type]]="Runs",_xlfn.IFS(Calculations_1[[#This Row],[Margin Value]]<=50,"1-50",Calculations_1[[#This Row],[Margin Value]]<=100,"51-100",Calculations_1[[#This Row],[Margin Value]]<=150,"101-150",Calculations_1[[#This Row],[Margin Value]]<=200,"151-200",TRUE,"201+"),"")} | Y6: {=IF(Calculations_1[[#This Row],[Winning Margin Type]]="Wickets",_xlfn.IFS(Calculations_1[[#This Row],[Margin Value]]<=3,"1-3",Calculations_1[[#This Row],[Margin Value]]<=6,"4-6",Calculations_1[[#This Row],[Margin Value]]<=10,"7-10"),"")} -> 4-6 | AA6: 3 | AB6: 45206 | AC6: Afghanistan | AD6: Bangladesh | AE6: Dharamshala | AF6: HPCA Stadium | AG6: Wickets | AH6: Chasing Won | AI6: 156 | AJ6: {=_xlfn.XLOOKUP( 1, (Table354[Match ID]=Table354[[#This Row],[Match ID]])* (Table354[Team]=Table354[[#This Row],[Opponent]]), Table354[Wickets Lost (batting)] )} -> 4 | AK6: 10 | AL6: 37.2 | AM6: 1 | AN6: 15 | AO6: 2 | AP6: 17 | AQ6: 4.17 | AR6: =_xlfn.XLOOKUP(Table354[[#This Row],[Match ID]],Calculations_1[Match ID],Calculations_1[Winning Team]) -> Bangladesh | AS6: 0 | AT6: 4 | AU6: 1 | AV6: 8 | AW6: =1 -> 1 | AX6: =IF(Table354[[#This Row],[Team]]=_xlfn.XLOOKUP(Table354[[#This Row],[Match ID]],Calculations_1[Match ID],Calculations_1[Winning Team]),1,0) -> 0 | AY6: =IF(NOT(Table354[[#This Row],[Win(1/0)]]),1,0) -> 1 | AZ6: =IF(Table354[[#This Row],[Win(1/0)]]=1,"Win","Loss") -> Loss | BA6: =IF(Table354[[#This Row],[Team]]=_xlfn.XLOOKUP(Table354[[#This Row],[Match ID]],Calculations_1[Match ID],Calculations_1[Toss Winner]),1,0) -> 0 | BB6: =Table354[[#This Row],[Win(1/0)]]*Table354[[#This Row],[Toss Won (1/0)]] -> 0 | BC6: {=_xlfn.XLOOKUP(Table354[[#This Row],[Match ID]],Calculations_1[Match ID],Calculations_1[Toss Decision],NA,0)} -> Field
A7: 6 | B7: =IF(ISNUMBER(Table1[[#This Row],[Match Date]]),DATE(YEAR(Table1[[#This Row],[Match Date]]),DAY(Table1[[#This Row],[Match Date]]),MONTH(Table1[[#This Row],[Match Date]])),DATE(VALUE(RIGHT(TRIM(Table1[[#This Row],[Match Date]]),4)),VALUE(MID(TRIM(Table1[[#This Row],[Match Date]]),4,2)),VALUE(LEFT(TRIM(Table1[[#This Row],[Match Date]]),2)))) -> 45208 | C7: =TRIM(Table1[[#This Row],[City]]) -> Hyderabad | D7: =IF(AND(TRIM(Table1[[#This Row],[Stadium]])="Eden Gardens",TRIM(Table1[[#This Row],[City]])<>"Kolkata"),"Rajiv Gandhi International Stadium",TRIM(Table1[[#This Row],[Stadium]])) -> Rajiv Gandhi International Stadium | E7: =SUBSTITUTE(Table1[[#This Row],[Team A]],"NewZealand","New Zealand") -> New Zealand | F7: =SUBSTITUTE(Table1[[#This Row],[Team B]],"NewZealand","New Zealand") -> Netherlands | G7: =SUBSTITUTE(Table1[[#This Row],[Toss Winner]],"NewZealand","New Zealand") -> Netherlands | H7: =SUBSTITUTE(Table1[[#This Row],[Wining Team]],"NewZealand","New Zealand") -> New Zealand | I7: =TRIM(Table1[[#This Row],[Toss Decision]]) -> Field | J7: =Table1[[#This Row],[Score A]] -> 322 | K7: =Table1[[#This Row],[Score B]] -> 223 | L7: =SUM(Calculations_1[[#This Row],[Score A]],Calculations_1[[#This Row],[Score B]]) -> 545 | M7: =SUM(Table1[[#This Row],[Wickets A]],Table1[[#This Row],[Wickets B]]) -> 17 | N7: =SUM(Table1[[#This Row],[4s A]],Table1[[#This Row],[4s B]]) -> 49 | O7: =SUM(Table1[[#This Row],[6s A]],Table1[[#This Row],[6s B]]) -> 13 | P7: =SUM(Calculations_1[[#This Row],[Total 4s (match)]],Calculations_1[[#This Row],[Total 6s (match)]]) -> 62 | Q7: =TRIM(Table1[[#This Row],[Margin]]) -> 99 Runs | R7: =VALUE(LEFT(Calculations_1[[#This Row],[Margin (text)]],FIND(" ",Calculations_1[[#This Row],[Margin (text)]])-1)) -> 99 | S7: =IF(ISNUMBER(SEARCH("DLS",Calculations_1[[#This Row],[Margin (text)]])),"Runs (DLS) Method",IF(ISNUMBER(SEARCH("run",Calculations_1[[#This Row],[Margin (text)]])),"Runs","Wickets")) -> Runs | T7: =IF(Calculations_1[[#This Row],[Winning Margin Type]]="Wickets","Chasing Won",IF(Calculations_1[[#This Row],[Winning Margin Type]]="Runs","Batting First Won","DLS Result")) -> Batting First Won | U7: =IF(Calculations_1[[#This Row],[Toss Winner]]=Calculations_1[[#This Row],[Winning Team]],1,0) -> 0 | V7: =IF(Calculations_1[[#This Row],[Toss Winner Won Match (1/0)]]=1,"Toss Winner Won","Toss Winner Lost") -> Toss Winner Lost | W7: =TRIM(Table1[[#This Row],[Man of the Match]]) -> Mitchell Santner | X7: {=IF(Calculations_1[[#This Row],[Winning Margin Type]]="Runs",_xlfn.IFS(Calculations_1[[#This Row],[Margin Value]]<=50,"1-50",Calculations_1[[#This Row],[Margin Value]]<=100,"51-100",Calculations_1[[#This Row],[Margin Value]]<=150,"101-150",Calculations_1[[#This Row],[Margin Value]]<=200,"151-200",TRUE,"201+"),"")} -> 51-100 | Y7: {=IF(Calculations_1[[#This Row],[Winning Margin Type]]="Wickets",_xlfn.IFS(Calculations_1[[#This Row],[Margin Value]]<=3,"1-3",Calculations_1[[#This Row],[Margin Value]]<=6,"4-6",Calculations_1[[#This Row],[Margin Value]]<=10,"7-10"),"")} | AA7: 3 | AB7: 45206 | AC7: Bangladesh | AD7: Afghanistan | AE7: Dharamshala | AF7: HPCA Stadium | AG7: Wickets | AH7: Chasing Won | AI7: 158 | AJ7: {=_xlfn.XLOOKUP( 1, (Table354[Match ID]=Table354[[#This Row],[Match ID]])* (Table354[Team]=Table354[[#This Row],[Opponent]]), Table354[Wickets Lost (batting)] )} -> 10 | AK7: 4 | AL7: 34.4 | AM7: 5 | AN7: 13 | AO7: 1 | AP7: 14 | AQ7: 4.55 | AR7: =_xlfn.XLOOKUP(Table354[[#This Row],[Match ID]],Calculations_1[Match ID],Calculations_1[Winning Team]) -> Bangladesh | AS7: 0 | AT7: 8 | AU7: 0 | AV7: 8 | AW7: =1 -> 1 | AX7: =IF(Table354[[#This Row],[Team]]=_xlfn.XLOOKUP(Table354[[#This Row],[Match ID]],Calculations_1[Match ID],Calculations_1[Winning Team]),1,0) -> 1 | AY7: =IF(NOT(Table354[[#This Row],[Win(1/0)]]),1,0) -> 0 | AZ7: =IF(Table354[[#This Row],[Win(1/0)]]=1,"Win","Loss") -> Win | BA7: =IF(Table354[[#This Row],[Team]]=_xlfn.XLOOKUP(Table354[[#This Row],[Match ID]],Calculations_1[Match ID],Calculations_1[Toss Winner]),1,0) -> 1 | BB7: =Table354[[#This Row],[Win(1/0)]]*Table354[[#This Row],[Toss Won (1/0)]] -> 1 | BC7: {=_xlfn.XLOOKUP(Table354[[#This Row],[Match ID]],Calculations_1[Match ID],Calculations_1[Toss Decision],NA,0)} -> Field
A8: 7 | B8: =IF(ISNUMBER(Table1[[#This Row],[Match Date]]),DATE(YEAR(Table1[[#This Row],[Match Date]]),DAY(Table1[[#This Row],[Match Date]]),MONTH(Table1[[#This Row],[Match Date]])),DATE(VALUE(RIGHT(TRIM(Table1[[#This Row],[Match Date]]),4)),VALUE(MID(TRIM(Table1[[#This Row],[Match Date]]),4,2)),VALUE(LEFT(TRIM(Table1[[#This Row],[Match Date]]),2)))) -> 45209 | C8: =TRIM(Table1[[#This Row],[City]]) -> Dharamshala | D8: =IF(AND(TRIM(Table1[[#This Row],[Stadium]])="Eden Gardens",TRIM(Table1[[#This Row],[City]])<>"Kolkata"),"Rajiv Gandhi International Stadium",TRIM(Table1[[#This Row],[Stadium]])) -> HPCA Stadium | E8: =SUBSTITUTE(Table1[[#This Row],[Team A]],"NewZealand","New Zealand") -> England | F8: =SUBSTITUTE(Table1[[#This Row],[Team B]],"NewZealand","New Zealand") -> Bangladesh | G8: =SUBSTITUTE(Table1[[#This Row],[Toss Winner]],"NewZealand","New Zealand") -> Bangladesh | H8: =SUBSTITUTE(Table1[[#This Row],[Wining Team]],"NewZealand","New Zealand") -> England | I8: =TRIM(Table1[[#This Row],[Toss Decision]]) -> Field | J8: =Table1[[#This Row],[Score A]] -> 364 | K8: =Table1[[#This Row],[Score B]] -> 227 | L8: =SUM(Calculations_1[[#This Row],[Score A]],Calculations_1[[#This Row],[Score B]]) -> 591 | M8: =SUM(Table1[[#This Row],[Wickets A]],Table1[[#This Row],[Wickets B]]) -> 19 | N8: =SUM(Table1[[#This Row],[4s A]],Table1[[#This Row],[4s B]]) -> 58 | O8: =SUM(Table1[[#This Row],[6s A]],Table1[[#This Row],[6s B]]) -> 10 | P8: =SUM(Calculations_1[[#This Row],[Total 4s (match)]],Calculations_1[[#This Row],[Total 6s (match)]]) -> 68 | Q8: =TRIM(Table1[[#This Row],[Margin]]) -> 137 Runs | R8: =VALUE(LEFT(Calculations_1[[#This Row],[Margin (text)]],FIND(" ",Calculations_1[[#This Row],[Margin (text)]])-1)) -> 137 | S8: =IF(ISNUMBER(SEARCH("DLS",Calculations_1[[#This Row],[Margin (text)]])),"Runs (DLS) Method",IF(ISNUMBER(SEARCH("run",Calculations_1[[#This Row],[Margin (text)]])),"Runs","Wickets")) -> Runs | T8: =IF(Calculations_1[[#This Row],[Winning Margin Type]]="Wickets","Chasing Won",IF(Calculations_1[[#This Row],[Winning Margin Type]]="Runs","Batting First Won","DLS Result")) -> Batting First Won | U8: =IF(Calculations_1[[#This Row],[Toss Winner]]=Calculations_1[[#This Row],[Winning Team]],1,0) -> 0 | V8: =IF(Calculations_1[[#This Row],[Toss Winner Won Match (1/0)]]=1,"Toss Winner Won","Toss Winner Lost") -> Toss Winner Lost | W8: =TRIM(Table1[[#This Row],[Man of the Match]]) -> Dawid Malan | X8: {=IF(Calculations_1[[#This Row],[Winning Margin Type]]="Runs",_xlfn.IFS(Calculations_1[[#This Row],[Margin Value]]<=50,"1-50",Calculations_1[[#This Row],[Margin Value]]<=100,"51-100",Calculations_1[[#This Row],[Margin Value]]<=150,"101-150",Calculations_1[[#This Row],[Margin Value]]<=200,"151-200",TRUE,"201+"),"")} -> 101-150 | Y8: {=IF(Calculations_1[[#This Row],[Winning Margin Type]]="Wickets",_xlfn.IFS(Calculations_1[[#This Row],[Margin Value]]<=3,"1-3",Calculations_1[[#This Row],[Margin Value]]<=6,"4-6",Calculations_1[[#This Row],[Margin Value]]<=10,"7-10"),"")} | AA8: 4 | AB8: 45206 | AC8: South Africa | AD8: Sri Lanka | AE8: Delhi | AF8: Arun Jaitley Stadium | AG8: Runs | AH8: Batting First Won | AI8: 428 | AJ8: {=_xlfn.XLOOKUP( 1, (Table354[Match ID]=Table354[[#This Row],[Match ID]])* (Table354[Team]=Table354[[#This Row],[Opponent]]), Table354[Wickets Lost (batting)] )} -> 10 | AK8: 5 | AL8: 50 | AM8: 1 | AN8: 45 | AO8: 14 | AP8: 59 | AQ8: 8.56 | AR8: =_xlfn.XLOOKUP(Table354[[#This Row],[Match ID]],Calculations_1[Match ID],Calculations_1[Winning Team]) -> South Africa | AS8: 0 | AT8: 14 | AU8: 1 | AV8: 20 | AW8: =1 -> 1 | AX8: =IF(Table354[[#This Row],[Team]]=_xlfn.XLOOKUP(Table354[[#This Row],[Match ID]],Calculations_1[Match ID],Calculations_1[Winning Team]),1,0) -> 1 | AY8: =IF(NOT(Table354[[#This Row],[Win(1/0)]]),1,0) -> 0 | AZ8: =IF(Table354[[#This Row],[Win(1/0)]]=1,"Win","Loss") -> Win | BA8: =IF(Table354[[#This Row],[Team]]=_xlfn.XLOOKUP(Table354[[#This Row],[Match ID]],Calculations_1[Match ID],Calculations_1[Toss Winner]),1,0) -> 0 | BB8: =Table354[[#This Row],[Win(1/0)]]*Table354[[#This Row],[Toss Won (1/0)]] -> 0 | BC8: {=_xlfn.XLOOKUP(Table354[[#This Row],[Match ID]],Calculations_1[Match ID],Calculations_1[Toss Decision],NA,0)} -> Field
A9: 8 | B9: =IF(ISNUMBER(Table1[[#This Row],[Match Date]]),DATE(YEAR(Table1[[#This Row],[Match Date]]),DAY(Table1[[#This Row],[Match Date]]),MONTH(Table1[[#This Row],[Match Date]])),DATE(VALUE(RIGHT(TRIM(Table1[[#This Row],[Match Date]]),4)),VALUE(MID(TRIM(Table1[[#This Row],[Match Date]]),4,2)),VALUE(LEFT(TRIM(Table1[[#This Row],[Match Date]]),2)))) -> 45209 | C9: =TRIM(Table1[[#This Row],[City]]) -> Hyderabad | D9: =IF(AND(TRIM(Table1[[#This Row],[Stadium]])="Eden Gardens",TRIM(Table1[[#This Row],[City]])<>"Kolkata"),"Rajiv Gandhi International Stadium",TRIM(Table1[[#This Row],[Stadium]])) -> Rajiv Gandhi International Stadium | E9: =SUBSTITUTE(Table1[[#This Row],[Team A]],"NewZealand","New Zealand") -> Sri Lanka | F9: =SUBSTITUTE(Table1[[#This Row],[Team B]],"NewZealand","New Zealand") -> Pakistan | G9: =SUBSTITUTE(Table1[[#This Row],[Toss Winner]],"NewZealand","New Zealand") -> Sri Lanka | H9: =SUBSTITUTE(Table1[[#This Row],[Wining Team]],"NewZealand","New Zealand") -> Pakistan | I9: =TRIM(Table1[[#This Row],[Toss Decision]]) -> Bat | J9: =Table1[[#This Row],[Score A]] -> 344 | K9: =Table1[[#This Row],[Score B]] -> 345 | L9: =SUM(Calculations_1[[#This Row],[Score A]],Calculations_1[[#This Row],[Score B]]) -> 689 | M9: =SUM(Table1[[#This Row],[Wickets A]],Table1[[#This Row],[Wickets B]]) -> 13 | N9: =SUM(Table1[[#This Row],[4s A]],Table1[[#This Row],[4s B]]) -> 62 | O9: =SUM(Table1[[#This Row],[6s A]],Table1[[#This Row],[6s B]]) -> 15 | P9: =SUM(Calculations_1[[#This Row],[Total 4s (match)]],Calculations_1[[#This Row],[Total 6s (match)]]) -> 77 | Q9: =TRIM(Table1[[#This Row],[Margin]]) -> 6 Wickets | R9: =VALUE(LEFT(Calculations_1[[#This Row],[Margin (text)]],FIND(" ",Calculations_1[[#This Row],[Margin (text)]])-1)) -> 6 | S9: =IF(ISNUMBER(SEARCH("DLS",Calculations_1[[#This Row],[Margin (text)]])),"Runs (DLS) Method",IF(ISNUMBER(SEARCH("run",Calculations_1[[#This Row],[Margin (text)]])),"Runs","Wickets")) -> Wickets | T9: =IF(Calculations_1[[#This Row],[Winning Margin Type]]="Wickets","Chasing Won",IF(Calculations_1[[#This Row],[Winning Margin Type]]="Runs","Batting First Won","DLS Result")) -> Chasing Won | U9: =IF(Calculations_1[[#This Row],[Toss Winner]]=Calculations_1[[#This Row],[Winning Team]],1,0) -> 0 | V9: =IF(Calculations_1[[#This Row],[Toss Winner Won Match (1/0)]]=1,"Toss Winner Won","Toss Winner Lost") -> Toss Winner Lost | W9: =TRIM(Table1[[#This Row],[Man of the Match]]) -> Mohammad Rizwan | X9: {=IF(Calculations_1[[#This Row],[Winning Margin Type]]="Runs",_xlfn.IFS(Calculations_1[[#This Row],[Margin Value]]<=50,"1-50",Calculations_1[[#This Row],[Margin Value]]<=100,"51-100",Calculations_1[[#This Row],[Margin Value]]<=150,"101-150",Calculations_1[[#This Row],[Margin Value]]<=200,"151-200",TRUE,"201+"),"")} | Y9: {=IF(Calculations_1[[#This Row],[Winning Margin Type]]="Wickets",_xlfn.IFS(Calculations_1[[#This Row],[Margin Value]]<=3,"1-3",Calculations_1[[#This Row],[Margin Value]]<=6,"4-6",Calculations_1[[#This Row],[Margin Value]]<=10,"7-10"),"")} -> 4-6 | AA9: 4 | AB9: 45206 | AC9: Sri Lanka | AD9: South Africa | AE9: Delhi | AF9: Arun Jaitley Stadium | AG9: Runs | AH9: Batting First Won | AI9: 326 | AJ9: {=_xlfn.XLOOKUP( 1, (Table354[Match ID]=Table354[[#This Row],[Match ID]])* (Table354[Team]=Table354[[#This Row],[Opponent]]), Table354[Wickets Lost (batting)] )} -> 5 | AK9: 10 | AL9: 44.5 | AM9: 1 | AN9: 31 | AO9: 17 | AP9: 48 | AQ9: 7.27 | AR9: =_xlfn.XLOOKUP(Table354[[#This Row],[Match ID]],Calculations_1[Match ID],Calculations_1[Winning Team]) -> South Africa | AS9: 0 | AT9: 21 | AU9: 1 | AV9: 23 | AW9: =1 -> 1 | AX9: =IF(Table354[[#This Row],[Team]]=_xlfn.XLOOKUP(Table354[[#This Row],[Match ID]],Calculations_1[Match ID],Calculations_1[Winning Team]),1,0) -> 0 | AY9: =IF(NOT(Table354[[#This Row],[Win(1/0)]]),1,0) -> 1 | AZ9: =IF(Table354[[#This Row],[Win(1/0)]]=1,"Win","Loss") -> Loss | BA9: =IF(Table354[[#This Row],[Team]]=_xlfn.XLOOKUP(Table354[[#This Row],[Match ID]],Calculations_1[Match ID],Calculations_1[Toss Winner]),1,0) -> 1 | BB9: =Table354[[#This Row],[Win(1/0)]]*Table354[[#This Row],[Toss Won (1/0)]] -> 0 | BC9: {=_xlfn.XLOOKUP(Table354[[#This Row],[Match ID]],Calculations_1[Match ID],Calculations_1[Toss Decision],NA,0)} -> Field
